Workbook

Sheet Resumen
A1: Incentivos de Volanteo - Escenario Actual y Estrategias de Pago
A3: Leyenda: | B3: Celda editable | D3: Celda calculada
A5: Regla base (no cambia en ninguna estrategia): 500 volanteos registrados y validados por TODO el equipo = S/200 de bono. Ya no existe un bono individual por persona.
A7: PARAMETROS
A8: Bono total por hito de 500 (S/) | B8: 200
A9: Umbral de avance intermedio (volanteos) | B9: 300
A10: Umbral final (volanteos) | B10: 500
A11: Estrategia 1 - Tramo 1 (S/) | B11: 100
A12: Estrategia 1 - Tramo 2 (S/) | B12: 100
A13: Estrategia 3 - Anticipo (S/) | B13: 70
A14: Estrategia 3 - Saldo (S/) | B14: 130
A15: Dias del ciclo actual (ventana maxima) | B15: 10
A16: Dias promedio real del ciclo actual | B16: 9
A17: Dias de la quincena (estrategias 1, 2 y 3) | B17: 15
A19: COMPARACION
A20: Opcion | B20: Estructura del bono | C20: Pagos maximos / mes | D20: Costo mensual estimado (S/)
A21: Escenario actual | B21: Pago unico S/200 cada 7-10 dias | C21: =30/B16 -> 3.3333333 | D21: =B8*(30/B16) -> 666.66667
A22: Estrategia 1 - Tramos iguales | B22: S/100 + S/100 por quincena | C22: =2 -> 2 | D22: =(B11+B12)*2 -> 400
A23: Estrategia 2 - Ventana larga | B23: Pago unico S/200 por quincena | C23: =2 -> 2 | D23: =B8*2 -> 400
A24: Estrategia 3 - Anticipo + saldo | B24: S/70 + S/130 por quincena | C24: =2 -> 2 | D24: =(B13+B14)*2 -> 400
A26: Techo natural de gasto con pago quincenal (2 pagos maximo/mes) | D26: =B8*2 -> 400
A27: Costo si el ciclo actual fuera siempre de 7 dias (peor caso para el bolsillo) | D27: =B8*(30/7) -> 857.14286
A29: Nota: las 3 estrategias no bajan el monto del bono (sigue siendo S/200 por hito), solo cambian cuando y en cuantas partes se paga. Al limitar el pago a la fecha de planilla quincenal, el gasto mensual queda topado en 2 pagos, sin importar que tan rapido cumpla el equipo.

Sheet Escenario Actual
A1: Escenario Actual - Bitacora de Ciclos Reales
A3: Como se usa:
A4: Cada fila es un ciclo real. Anota cuantos dias tardo TODO el equipo en juntar 500 volanteos registrados.
A6: Ciclo | B6: Dia de inicio | C6: Dias que tardaron en llegar a 500 | D6: Dia de corte | E6: Llego dentro de la ventana? | F6: Bono pagado (S/) | G6: Dentro del mes (dia <= 30)?
A7: 1 | B7: 1 | C7: 7 | D7: =B7+C7-1 -> 7 | E7: =IF(C7<=Resumen!$B$15,"Si","No") -> Si | F7: =IF(E7="Si",Resumen!$B$8,0) -> 200 | G7: =IF(D7<=30,"Si","No") -> Si
A8: 2 | B8: =D7+1 -> 8 | C8: 9 | D8: =B8+C8-1 -> 16 | E8: =IF(C8<=Resumen!$B$15,"Si","No") -> Si | F8: =IF(E8="Si",Resumen!$B$8,0) -> 200 | G8: =IF(D8<=30,"Si","No") -> Si
A9: 3 | B9: =D8+1 -> 17 | C9: 8 | D9: =B9+C9-1 -> 24 | E9: =IF(C9<=Resumen!$B$15,"Si","No") -> Si | F9: =IF(E9="Si",Resumen!$B$8,0) -> 200 | G9: =IF(D9<=30,"Si","No") -> Si
A10: 4 | B10: =D9+1 -> 25 | C10: 10 | D10: =B10+C10-1 -> 34 | E10: =IF(C10<=Resumen!$B$15,"Si","No") -> Si | F10: =IF(E10="Si",Resumen!$B$8,0) -> 200 | G10: =IF(D10<=30,"Si","No") -> No
A11: 5 | B11: =D10+1 -> 35 | C11: 9 | D11: =B11+C11-1 -> 43 | E11: =IF(C11<=Resumen!$B$15,"Si","No") -> Si | F11: =IF(E11="Si",Resumen!$B$8,0) -> 200 | G11: =IF(D11<=30,"Si","No") -> No
A12: 6 | B12: =D11+1 -> 44 | C12: 8 | D12: =B12+C12-1 -> 51 | E12: =IF(C12<=Resumen!$B$15,"Si","No") -> Si | F12: =IF(E12="Si",Resumen!$B$8,0) -> 200 | G12: =IF(D12<=30,"Si","No") -> No
A14: RESUMEN DEL MES
A15: Ciclos que cerraron dentro del mes | D15: =COUNTIF(G7:G12,"Si") -> 3
A16: Bono total pagado en el mes (S/) | D16: =SUMPRODUCT((G7:G12="Si")*F7:F12) -> 600

Sheet Estrategias por Quincena
A1: Comparacion de las 3 Estrategias, Quincena a Quincena
A3: Como se usa:
A4: Por cada quincena, anota en que dia (1 a 15) el equipo llego a 300 y a 500 volanteos registrados. Deja en blanco si no llegaron. Las 3 estrategias se calculan solas, a partir de los mismos 2 datos.
A6: Quincena | B6: Dia en que llegaron a 300 (1-15) | C6: Dia en que llegaron a 500 (1-15) | D6: Pago Estrategia 1 (S/) | E6: Pago Estrategia 2 (S/) | F6: Pago Estrategia 3 (S/)
A7: 1 | B7: 6 | C7: 9 | D7: =IF(AND(ISNUMBER(B7),B7<=Resumen!$B$17),Resumen!$B$11,0)+IF(AND(ISNUMBER(C7),C7<=Resumen!$B$17),Resumen!$B$12,0) -> 200 | E7: =IF(AND(ISNUMBER(C7),C7<=Resumen!$B$17),Resumen!$B$8,0) -> 200 | F7: =IF(AND(ISNUMBER(B7),B7<=Resumen!$B$17),Resumen!$B$13,0)+IF(AND(ISNUMBER(C7),C7<=Resumen!$B$17),Resumen!$B$14,0) -> 200
A8: 2 | B8: 8 | C8: 14 | D8: =IF(AND(ISNUMBER(B8),B8<=Resumen!$B$17),Resumen!$B$11,0)+IF(AND(ISNUMBER(C8),C8<=Resumen!$B$17),Resumen!$B$12,0) -> 200 | E8: =IF(AND(ISNUMBER(C8),C8<=Resumen!$B$17),Resumen!$B$8,0) -> 200 | F8: =IF(AND(ISNUMBER(B8),B8<=Resumen!$B$17),Resumen!$B$13,0)+IF(AND(ISNUMBER(C8),C8<=Resumen!$B$17),Resumen!$B$14,0) -> 200
A9: 3 | B9: 5 | C9: 8 | D9: =IF(AND(ISNUMBER(B9),B9<=Resumen!$B$17),Resumen!$B$11,0)+IF(AND(ISNUMBER(C9),C9<=Resumen!$B$17),Resumen!$B$12,0) -> 200 | E9: =IF(AND(ISNUMBER(C9),C9<=Resumen!$B$17),Resumen!$B$8,0) -> 200 | F9: =IF(AND(ISNUMBER(B9),B9<=Resumen!$B$17),Resumen!$B$13,0)+IF(AND(ISNUMBER(C9),C9<=Resumen!$B$17),Resumen!$B$14,0) -> 200
A10: 4 | B10: 9 | D10: =IF(AND(ISNUMBER(B10),B10<=Resumen!$B$17),Resumen!$B$11,0)+IF(AND(ISNUMBER(C10),C10<=Resumen!$B$17),Resumen!$B$12,0) -> 100 | E10: =IF(AND(ISNUMBER(C10),C10<=Resumen!$B$17),Resumen!$B$8,0) -> 0 | F10: =IF(AND(ISNUMBER(B10),B10<=Resumen!$B$17),Resumen!$B$13,0)+IF(AND(ISNUMBER(C10),C10<=Resumen!$B$17),Resumen!$B$14,0) -> 70
A11: TOTAL | D11: =SUM(D7:D10) -> 700 | E11: =SUM(E7:E10) -> 600 | F11: =SUM(F7:F10) -> 670
A13: Promedio mensual (2 quincenas = 1 mes) | D13: =D11/(4/2) -> 350 | E13: =E11/(4/2) -> 300 | F13: =F11/(4/2) -> 335
A15: Nota: con estos 4 ejemplos (2 meses), se ve que las 3 estrategias reparten el mismo dinero de forma distinta segun que tan rapido llega el equipo a cada umbral. Cambia los dias de ejemplo por tus datos reales para comparar.

Sheet Datos de Campo (Rodrigo)
A1: Datos de Campo - Reunion con Rodrigo (24 set.)
A3: Leyenda: | B3: Celda editable | D3: Celda calculada
A5: PARAMETROS REALES
A6: Personas fijas confirmadas (Marcia) | B6: 8
A7: Meta individual (volanteos/persona/dia) | B7: 100
A8: Sueldo minimo mensual referencial (S/) | B8: 1130
A9: Dias laborables / mes (para el asesor) | B9: 26
A10: Comision sugerida por afiliacion al asesor (S/) | B10: 2
A11: Bono de equipo en negociacion - minimo (S//dia) | B11: 120
A12: Bono de equipo en negociacion - recomendado (S//dia) | B12: 150
A13: Bono de equipo en negociacion - maximo (S//dia) | B13: 160
A14: Dias de pago considerados por semana | B14: 5
A15: Dias que trabaja el equipo por mes | B15: 26
A17: PISO ECONOMICO (sanity check de la meta)
A18: Sueldo minimo por dia (S/) | B18: =B8/B9 -> 43.461538
A19: Afiliaciones/dia necesarias para igualar el sueldo minimo (a la comision de arriba) | B19: =(B8/B9)/B10 -> 21.730769
A20: Equivalente por hora (jornada de 8h) | B20: =B19/8 -> 2.7163462
A21: Meta de 100/dia vs. ese piso (veces) | B21: =B7/B19 -> 4.6017699
A23: BONO DE EQUIPO - EQUIVALENTES
B24: Minimo | C24: Recomendado | D24: Maximo
A25: Por dia (S/) | B25: =B11 -> 120 | C25: =B12 -> 150 | D25: =B13 -> 160
A26: Por semana (S/) | B26: =B11*$B$14 -> 600 | C26: =B12*$B$14 -> 750 | D26: =B13*$B$14 -> 800
A27: Por mes (S/) | B27: =B11*$B$15 -> 3120 | C27: =B12*$B$15 -> 3900 | D27: =B13*$B$15 -> 4160
A29: RECOMENDACIONES OPERATIVAS DE LA LLAMADA
A30: Horario recomendado
A31: Casi no hay movimiento en la manana; sube desde el mediodia y el pico mas alto es a las 7:00 p.m., con buen movimiento entre 5 y 9 p.m. Sugerencia: turnos de 12 p.m. a 9 p.m. (o 1 a 9), en vez de horario de oficina.
A33: Elegibilidad ampliada
A34: El bono ya no aplica solo a afiliaciones GNV: ahora cuenta la afiliacion de cualquier tipo de vehiculo, lo que hace la meta mas facil de alcanzar.
A36: Quien decide el reparto interno
A37: Nosotros damos el bono de equipo y los datos de horas pico. Como Marcia reparte ese dinero entre sus 8 fijos y como arma los turnos, es decision de ella.
A39: NOTA DE RECONCILIACION CON LA HOJA 'RESUMEN'
A40: Este bono de equipo (S/120-160/dia, recomendado S/150) es la cifra real que salio de la negociacion con Marcia y con Rodrigo. Reemplaza al S/200 por cada 500 volanteos que se uso como referencia inicial en la hoja 'Resumen'. Antes de tomar una decision final con las hojas 'Escenario Actual' y 'Estrategias por Quincena', actualiza el parametro 'Bono total por hito' de la hoja Resumen con el monto que se termine de negociar aqui, y ajusta 'Numero de personas fijas' a 8 donde aplique.

Sheet Analisis Real y Calculadora
A1: Analisis Real de Afiliaciones y Calculadora de Meta
A3: Leyenda: | B3: Celda editable | D3: Celda calculada
A5: DATOS REALES - EQUIPO FIJO DE MARCIA (por semana)
A6: Semana | B6: Rango de fechas | C6: Afiliaciones reales
A7: Semana 1 | B7: 31 ago - 6 set | C7: 50
A8: Semana 2 | B8: 7 - 13 set | C8: 91
A9: Semana 3 | B9: 14 - 20 set | C9: 31
A10: Semana 4 | B10: 21 - 27 set | C10: 41
A11: Promedio semanal real | C11: =AVERAGE(C7:C10) -> 53.25
A12: Minimo semanal real | C12: =MIN(C7:C10) -> 31
A13: Maximo semanal real | C13: =MAX(C7:C10) -> 91
A15: DATOS REALES - RED GENERAL DE SCOUTS (por semana completa)
A16: Semana | B16: Rango de fechas | C16: Afiliaciones reales
A17: Semana 1 | B17: 17 - 23 ago | C17: 45
A18: Semana 2 | B18: 24 - 30 ago | C18: 101
A19: Semana 3 | B19: 31 ago - 6 set | C19: 57
A20: Semana 4 | B20: 7 - 13 set | C20: 58
A21: Semana 5 | B21: 14 - 20 set | C21: 108
A22: Promedio / referencia (red de scouts) | C22: =AVERAGE(C17:C21) -> 73.8
A24: QUINCENAS REALES (2 semanas seguidas, equipo de Marcia)
A25: Quincena | B25: Suma de 2 semanas seguidas
A26: S1+S2 | B26: 141
A27: S2+S3 | B27: 122
A28: S3+S4 | B28: 72
A29: Minimo / Maximo quincenal real | B29: =MIN(B26:B28) -> 72 | C29: =MAX(B26:B28) -> 141
A31: PROYECCIONES (extrapoladas del ritmo semanal real)
A32: Semanas por mes (factor de extrapolacion) | B32: 4.33
A33: Minimo mensual estimado (= minimo semanal x semanas/mes) | B33: =C12*B32 -> 134.23
A34: Maximo mensual estimado (= maximo semanal x semanas/mes) | B34: =C13*B32 -> 394.03
A35: Minimo estimado a 2 meses | B35: =C12*B32*2 -> 268.46
A36: Maximo estimado a 2 meses | B36: =C13*B32*2 -> 788.06
A38: CALCULADORA - ELIGE UNA META (minimo 500, por regla del negocio)
A39: Meta de volanteos (minimo 500) | B39: 500
A40: Periodo (escribe: Semana, Quincena, Mes o Dos meses) | B40: Mes
A41: Bono por periodo cumplido (S/) | B41: 200
A43: RESULTADOS
A44: Minimo real/estimado de referencia | B44: =IF(B40="Semana",C12,IF(B40="Quincena",B29,IF(B40="Mes",B33,B35))) -> 134.23
A45: Maximo real/estimado de referencia | B45: =IF(B40="Semana",C13,IF(B40="Quincena",C29,IF(B40="Mes",B34,B36))) -> 394.03
A46: Factibilidad de la meta elegida | B46: =IF(B39<=B45,"Dentro de lo ya logrado",IF(B39<=B45*1.3,"Exigente, cerca de su mejor marca","Muy por encima de lo demostrado")) -> Exigente, cerca de su mejor marca
A47: Veces que se paga al mes | B47: =IF(B40="Semana",30/7,IF(B40="Quincena",30/15,IF(B40="Mes",1,0.5))) -> 1
...
